<?xml version="1.0" ?>
<!-- =================================================================================== -->
<!-- |    This document was autogenerated by xacro from chaser_create.urdf.xacro       | -->
<!-- |    EDITING THIS FILE BY HAND IS NOT RECOMMENDED                                 | -->
<!-- =================================================================================== -->
<robot name="chaser" xmlns:xacro="http://ros.org/wiki/xacro">
  <!--scaling factor for maximum velocity - for testing purposes-->
  <!--value="-0.032"-->
  <link name="base_link">
    <inertial>
      <origin rpy="0 0 0" xyz="-0.0017516 -4.7676E-17 -1.6851E-06"/>
      <mass value="255"/>
      <inertia ixx="3.87199388339" ixy="0" ixz="7.527E-07" iyy="3.81565926076" iyz="0" izz="3.81565926004"/>
      <!--ixx="3.872" ixz="7.527E-07" -->
    </inertial>
    <visual>
      <geometry>
        <mesh filename="package://chaser_description/models/robot1.0/meshes/base.dae"/>
      </geometry>
    </visual>
    <collision>
      <geometry>
        <mesh filename="package://chaser_description/models/robot1.0/meshes/base_col.STL"/>
      </geometry>
    </collision>
  </link>
  <link name="arm0">
    <inertial>
      <origin rpy="0 0 0" xyz="5.3585E-09 -0.0072243 0.030704"/>
      <mass value="2.188"/>
      <inertia ixx="0.00399551133" ixy="0" ixz="5.5E-10" iyy="0.00355787709" iyz="-0.00073817117" izz="0.00193246625"/>
    </inertial>
    <visual>
      <geometry>
        <mesh filename="package://chaser_description/models/robot1.0/meshes/arm0.dae"/>
      </geometry>
    </visual>
    <collision>
      <geometry>
        <mesh filename="package://chaser_description/models/robot1.0/meshes/arm0_col.STL"/>
      </geometry>
    </collision>
  </link>
  <link name="arm1">
    <inertial>
      <origin rpy="0 0 0" xyz="0.089479 -3.5914E-05 0.00091428"/>
      <mass value="2.08"/>
      <inertia ixx="0.00042854156" ixy="-6.22362E-06" ixz="0.00031695013" iyy="0.02580489818" iyz="1.9E-10" izz="0.025805"/>
    </inertial>
    <visual>
      <geometry>
        <mesh filename="package://chaser_description/models/robot1.0/meshes/arm1.dae"/>
      </geometry>
    </visual>
    <collision>
      <geometry>
        <mesh filename="package://chaser_description/models/robot1.0/meshes/arm1_col.STL"/>
      </geometry>
    </collision>
  </link>
  <link name="arm2">
    <inertial>
      <origin rpy="0 0 0" xyz="0.0014573 7.1511E-05 0.018982"/>
      <mass value="0.68"/>
      <inertia ixx="0.00041100473" ixy="2.213E-07" ixz="1.783718E-05" iyy="0.00041140107" iyz="8.7529E-07" izz="0.00018778756"/>
    </inertial>
    <visual>
      <geometry>
        <mesh filename="package://chaser_description/models/robot1.0/meshes/arm2.dae"/>
      </geometry>
    </visual>
    <collision>
      <geometry>
        <mesh filename="package://chaser_description/models/robot1.0/meshes/arm2_col.STL"/>
      </geometry>
    </collision>
  </link>
  <link name="arm2_1">
    <inertial>
      <origin rpy="0 0 0" xyz="2.4616E-05 -0.00048515 0.094009"/>
      <mass value="1.403"/>
      <inertia ixx="0.01502106284" ixy="0" ixz="5.17588E-06" iyy="0.01504326724" iyz="-3.01782E-06" izz="0.0002400667"/>
    </inertial>
    <visual>
      <geometry>
        <mesh filename="package://chaser_description/models/robot1.0/meshes/arm2_1.dae"/>
      </geometry>
    </visual>
    <collision>
      <geometry>
        <mesh filename="package://chaser_description/models/robot1.0/meshes/arm2_1_col.STL"/>
      </geometry>
    </collision>
  </link>
  <link name="arm3">
    <inertial>
      <origin rpy="0 0 0" xyz="0.0011084 -1.6282E-17 -0.019487"/>
      <mass value="0.673"/>
      <inertia ixx="0.00038763111" ixy="0" ixz="-1.342736E-05" iyy="0.00038781652" iyz="0" izz="0.00012351201"/>
    </inertial>
    <visual>
      <geometry>
        <mesh filename="package://chaser_description/models/robot1.0/meshes/arm3.dae"/>
      </geometry>
    </visual>
    <collision>
      <geometry>
        <mesh filename="package://chaser_description/models/robot1.0/meshes/arm3_col.STL"/>
      </geometry>
    </collision>
  </link>
  <link name="arm3_1">
    <inertial>
      <origin rpy="0 0 0" xyz="1.1435E-17 -3.4617E-17 0.050778"/>
      <mass value="0.674"/>
      <inertia ixx="0.00240933695" ixy="0" ixz="0" iyy="0.00240933695" iyz="0" izz="7.244164E-05"/>
    </inertial>
    <visual>
      <geometry>
        <mesh filename="package://chaser_description/models/robot1.0/meshes/arm3_1.dae"/>
      </geometry>
    </visual>
    <collision>
      <origin rpy="0 0 0" xyz="0 0 0"/>
      <geometry>
        <mesh filename="package://chaser_description/models/robot1.0/meshes/arm3_1_col.STL"/>
      </geometry>
    </collision>
  </link>
  <link name="hand_base">
    <inertial>
      <origin rpy="0 0 0" xyz="-2.0891E-17 -4.2343E-17 0.026583"/>
      <mass value="1E-6"/>
      <inertia ixx="1.667E-13" ixy="0" ixz="0" iyy="1.667E-13" iyz="0" izz="1.667E-13"/>
    </inertial>
    <visual>
      <geometry>
        <box size="0.0025 0.0025 0.0025"/>
      </geometry>
    </visual>
    <collision name="hand_base">
      <geometry>
        <box size="0.0025 0.0025 0.0025"/>
      </geometry>
    </collision>
  </link>
  <link name="hand">
    <inertial>
      <origin rpy="0 0 0" xyz="-2.0891E-17 -4.2343E-17 0.026583"/>
      <!--xyz="-2.0891E-17 -4.2343E-17 0.026583"-->
      <mass value="0.283"/>
      <inertia ixx="0.00027210077" ixy="0" ixz="0" iyy="0.00027210077" iyz="0" izz="3.1537E-05"/>
    </inertial>
    <visual>
      <geometry>
        <mesh filename="package://chaser_description/models/robot1.0/meshes/hand.dae"/>
      </geometry>
    </visual>
    <collision>
      <!--it is necessary to name the collision to be able to use the contact sensor-->
      <geometry>
        <mesh filename="package://chaser_description/models/robot1.0/meshes/hand_col.STL"/>
      </geometry>
    </collision>
  </link>
  <joint name="j1" type="revolute">
    <origin rpy="0 1.5708 0" xyz="0.10324 0 0"/>
    <parent link="base_link"/>
    <child link="arm0"/>
    <axis xyz="0 0 1"/>
    <limit effort="10" lower="-3.2289" upper="3.2289" velocity="2443.5"/>
    <calibration rising="0.0"/>
    <dynamics damping="0.2" friction="0.5"/>
    <safety_controller k_position="15" k_velocity="10" soft_lower_limit="-2.90601" soft_upper_limit="2.90601"/>
  </joint>
  <transmission name="j1_trans">
    <type>transmission_interface/SimpleTransmission</type>
    <joint name="j1">
      <hardwareInterface>EffortJointInterface</hardwareInterface>
    </joint>
    <actuator name="j1_motor">
      <hardwareInterface>EffortJointInterface</hardwareInterface>
      <mechanicalReduction>1</mechanicalReduction>
    </actuator>
  </transmission>
  <joint name="j2" type="revolute">
    <origin rpy="1.5708 -0.7854 -3.1416" xyz="0 0 0.0467"/>
    <parent link="arm0"/>
    <child link="arm1"/>
    <axis xyz="0 0 1"/>
    <limit effort="10000000.0" lower="-0.59341" upper="2.1642" velocity="2199.1"/>
    <calibration rising="0.0"/>
    <dynamics damping="0.2" friction="0.5"/>
    <safety_controller k_position="15" k_velocity="10" soft_lower_limit="-0.534069" soft_upper_limit="1.94778"/>
  </joint>
  <transmission name="j2_trans">
    <type>transmission_interface/SimpleTransmission</type>
    <joint name="j2">
      <hardwareInterface>EffortJointInterface</hardwareInterface>
    </joint>
    <actuator name="j2_motor">
      <hardwareInterface>EffortJointInterface</hardwareInterface>
      <mechanicalReduction>1</mechanicalReduction>
    </actuator>
  </transmission>
  <joint name="j3" type="revolute">
    <origin rpy="0 0 1.5708" xyz="0.16667 0 0.021"/>
    <parent link="arm1"/>
    <child link="arm2"/>
    <axis xyz="0 0 1"/>
    <limit effort="10000000.0" lower="-4.311" upper="1.1694" velocity="2199.1"/>
    <calibration rising="0.0"/>
    <dynamics damping="0.2" friction="0.5"/>
    <safety_controller k_position="15" k_velocity="10" soft_lower_limit="-3.8799" soft_upper_limit="1.05246"/>
  </joint>
  <transmission name="j3_trans">
    <type>transmission_interface/SimpleTransmission</type>
    <joint name="j3">
      <hardwareInterface>EffortJointInterface</hardwareInterface>
    </joint>
    <actuator name="j3_motor">
      <hardwareInterface>EffortJointInterface</hardwareInterface>
      <mechanicalReduction>1</mechanicalReduction>
    </actuator>
  </transmission>
  <joint name="j4" type="revolute">
    <origin rpy="1.5708 0 1.5708" xyz="0.021 0 0.018"/>
    <parent link="arm2"/>
    <child link="arm2_1"/>
    <axis xyz="0 0 1"/>
    <limit effort="10000000.0" lower="-6.1087" upper="6.1087" velocity="4537.9"/>
    <!--symmetric-->
    <calibration rising="0.0"/>
    <dynamics damping="0.2" friction="0.5"/>
    <safety_controller k_position="15" k_velocity="10" soft_lower_limit="-5.49783" soft_upper_limit="5.49783"/>
    <!--symmetric-->
  </joint>
  <transmission name="j4_trans">
    <type>transmission_interface/SimpleTransmission</type>
    <joint name="j4">
      <hardwareInterface>EffortJointInterface</hardwareInterface>
    </joint>
    <actuator name="j4_motor">
      <hardwareInterface>EffortJointInterface</hardwareInterface>
      <mechanicalReduction>1</mechanicalReduction>
    </actuator>
  </transmission>
  <joint name="j5" type="revolute">
    <origin rpy="1.5708 -0.78541 3.1416" xyz="0 -0.021 0.14567"/>
    <parent link="arm2_1"/>
    <child link="arm3"/>
    <axis xyz="0 0 1"/>
    <limit effort="10000000.0" lower="-2.0595" upper="3.6303" velocity="4276.1"/>
    <calibration rising="0.0"/>
    <dynamics damping="0.2" friction="0.5"/>
    <safety_controller k_position="15" k_velocity="10" soft_lower_limit="-1.85355" soft_upper_limit="3.26727"/>
  </joint>
  <transmission name="j5_trans">
    <type>transmission_interface/SimpleTransmission</type>
    <joint name="j5">
      <hardwareInterface>EffortJointInterface</hardwareInterface>
    </joint>
    <actuator name="j5_motor">
      <hardwareInterface>EffortJointInterface</hardwareInterface>
      <mechanicalReduction>1</mechanicalReduction>
    </actuator>
  </transmission>
  <joint name="j6" type="revolute">
    <origin rpy="1.5708 0 1.5708" xyz="0.01717 0 -0.018"/>
    <parent link="arm3"/>
    <child link="arm3_1"/>
    <axis xyz="0 0 1"/>
    <limit effort="10000000.0" lower="-6.1087" upper="6.1087" velocity="5620.0"/>
    <!--symmetric and equal to j4-->
    <calibration rising="0.0"/>
    <dynamics damping="0.2" friction="0.5"/>
    <safety_controller k_position="15" k_velocity="10" soft_lower_limit="-5.49783" soft_upper_limit="5.49783"/>
    <!--symmetric-->
  </joint>
  <transmission name="j6_trans">
    <type>transmission_interface/SimpleTransmission</type>
    <joint name="j6">
      <hardwareInterface>EffortJointInterface</hardwareInterface>
    </joint>
    <actuator name="j6_motor">
      <hardwareInterface>EffortJointInterface</hardwareInterface>
      <mechanicalReduction>1</mechanicalReduction>
    </actuator>
  </transmission>
  <joint name="f1" type="prismatic">
    <origin rpy="0 0 0" xyz="0 0 -0.16"/>
    <!-- xyz="0 0 0.12 ->0.1175"-->
    <parent link="hand_base"/>
    <child link="hand"/>
    <axis xyz="0 0 1"/>
    <limit effort="10000000.0" lower="0.00" upper="0.00" velocity="0"/>
  </joint>
  <joint name="d1" type="prismatic">
    <origin rpy="0 0 0" xyz="0 0 0.15"/>
    <!-- xyz="0 0 0.12"     0.235=2*0.1175-->
    <parent link="arm3_1"/>
    <child link="hand_base"/>
    <axis xyz="0 0 1"/>
    <limit effort="10000000.0" lower="-0.032" upper="0.00" velocity="2500.0"/>
    <dynamics damping="1.4" friction="0.0"/>
    <!-- 1.4 , 2.7 -->
    <!--spring stiffness is implemented in a plugin-->
  </joint>
  <transmission name="d1_trans">
    <type>transmission_interface/SimpleTransmission</type>
    <joint name="d1">
      <hardwareInterface>EffortJointInterface</hardwareInterface>
    </joint>
    <actuator name="d1_motor">
      <hardwareInterface>EffortJointInterface</hardwareInterface>
      <mechanicalReduction>1</mechanicalReduction>
    </actuator>
  </transmission>
  <!--dummy effort joint interface-->
  <transmission name="f1_trans">
    <type>transmission_interface/SimpleTransmission</type>
    <joint name="f1">
      <hardwareInterface>EffortJointInterface</hardwareInterface>
    </joint>
    <actuator name="f1_motor">
      <hardwareInterface>EffortJointInterface</hardwareInterface>
      <mechanicalReduction>1</mechanicalReduction>
    </actuator>
  </transmission>
  <!--dummy effort joint interface-->
  <link name="world"/>
  <!-- Attach the model to Gazebo-->
  <joint name="base_joint" type="fixed">
    <parent link="world"/>
    <child link="base_link"/>
  </joint>
  <!--ROS CONTROL PLUGIN-->
  <gazebo>
    <plugin filename="libgazebo_ros_control.so" name="gazebo_ros_control">
      <robotNamespace>/chaser</robotNamespace>
      <robotSimType>gazebo_ros_control/DefaultRobotHWSim</robotSimType>
    </plugin>
  </gazebo>
  <gazebo reference="base_link">
    <mu1>0.2</mu1>
    <mu2>0.2</mu2>
    <kp>2147483647.0</kp>
    <kd>1</kd>
    <selfCollide>false</selfCollide>
    <maxVel>0.01</maxVel>
    <minDepth>0.003</minDepth>
  </gazebo>
  <gazebo reference="arm0">
    <mu1>0.2</mu1>
    <mu2>0.2</mu2>
    <kp>2147483647.0</kp>
    <kd>1</kd>
    <selfCollide>false</selfCollide>
    <maxVel>0.01</maxVel>
    <minDepth>0.003</minDepth>
  </gazebo>
  <gazebo reference="arm1">
    <mu1>0.2</mu1>
    <mu2>0.2</mu2>
    <kp>2147483647.0</kp>
    <kd>1</kd>
    <selfCollide>false</selfCollide>
    <maxVel>0.01</maxVel>
    <minDepth>0.003</minDepth>
  </gazebo>
  <gazebo reference="arm2">
    <mu1>0.2</mu1>
    <mu2>0.2</mu2>
    <kp>2147483647.0</kp>
    <kd>1</kd>
    <selfCollide>false</selfCollide>
    <maxVel>0.01</maxVel>
    <minDepth>0.003</minDepth>
  </gazebo>
  <gazebo reference="arm2_1">
    <mu1>0.2</mu1>
    <mu2>0.2</mu2>
    <kp>2147483647.0</kp>
    <kd>1</kd>
    <selfCollide>false</selfCollide>
    <maxVel>0.01</maxVel>
    <minDepth>0.003</minDepth>
  </gazebo>
  <gazebo reference="arm3">
    <mu1>0.2</mu1>
    <mu2>0.2</mu2>
    <kp>2147483647.0</kp>
    <kd>1</kd>
    <selfCollide>false</selfCollide>
    <maxVel>0.01</maxVel>
    <minDepth>0.003</minDepth>
  </gazebo>
  <gazebo reference="arm3_1">
    <mu1>0.2</mu1>
    <mu2>0.2</mu2>
    <kp>2147483647.0</kp>
    <kd>1</kd>
    <selfCollide>false</selfCollide>
    <maxVel>0.01</maxVel>
    <minDepth>0.003</minDepth>
  </gazebo>
  <gazebo reference="hand">
    <mu1>0.2</mu1>
    <mu2>0.2</mu2>
    <kp>2147483647.0</kp>
    <kd>1</kd>
    <selfCollide>false</selfCollide>
    <maxVel>0.01</maxVel>
    <minDepth>0.003</minDepth>
  </gazebo>
  <!--GAZEBO PHYSICS IN JOINTS-->
  <gazebo reference="j1">
    <implicitSpringDamper>1</implicitSpringDamper>
    <provideFeedback>1</provideFeedback>
  </gazebo>
  <gazebo reference="j2">
    <implicitSpringDamper>1</implicitSpringDamper>
    <provideFeedback>1</provideFeedback>
  </gazebo>
  <gazebo reference="j3">
    <implicitSpringDamper>1</implicitSpringDamper>
    <provideFeedback>1</provideFeedback>
  </gazebo>
  <gazebo reference="j4">
    <implicitSpringDamper>1</implicitSpringDamper>
    <provideFeedback>1</provideFeedback>
  </gazebo>
  <gazebo reference="j5">
    <implicitSpringDamper>1</implicitSpringDamper>
    <provideFeedback>1</provideFeedback>
  </gazebo>
  <gazebo reference="j6">
    <implicitSpringDamper>1</implicitSpringDamper>
    <provideFeedback>1</provideFeedback>
  </gazebo>
  <gazebo reference="d1">
    <implicitSpringDamper>1</implicitSpringDamper>
    <provideFeedback>1</provideFeedback>
  </gazebo>
  <gazebo reference="f1">
    <implicitSpringDamper>1</implicitSpringDamper>
    <provideFeedback>1</provideFeedback>
  </gazebo>
  <!--PLUGIN FOR COMPLIANT WRIST (SPRING) -->
  <gazebo>
    <plugin filename="libcompliant_wrist.so" name="compliant_wrist"/>
  </gazebo>
  <gazebo reference="hand">
    <sensor name="hand_contact_sensor" type="contact">
      <contact>
        <collision>hand_collision</collision>
      </contact>
      <plugin filename="libgazebo_ros_bumper.so" name="hand_gazebo_ros_bumper_controller">
        <alwaysOn>true</alwaysOn>
        <updateRate>30</updateRate>
        <bumperTopicName>chaser/hand_bumper</bumperTopicName>
        <frameName>world</frameName>
      </plugin>
    </sensor>
  </gazebo>
  <!--FORCE TORQUE SENSOR PLUGIN-->
  <!--xacro:ft_sensor name="s1" update_rate="${upd_rate}"/-->
</robot>
<!--parent link="world"/-->

